Workbook

Sheet READ ME
A1: Temptation Token — Sell This Software Plan v2 (Sept 25, 2026)
A2: Built on the Sept 19 agency workbook. Every Sept 19 tab is kept (Targets, Scoring Model, Events, EV Calculator); the sale-plan tabs are new. Sender identity for all TTS correspondence: jim@temptationtoken.io.
A4: DASHBOARD
A5: Offer review date | B5: =DATE(2026,10,16)
A6: Days until offer review | B6: =MAX(0,B5-TODAY())
A7: Plan tasks | B7: =COUNTA(Plan!A2:A200)
A8: Plan tasks marked Done | B8: =COUNTIF(Plan!I2:I200,"Done")
A9: Plan completion | B9: =IF(B7=0,0,B8/B7)
A10: Acquirers on the list | B10: =COUNTIF(Acquirers!A2:A100,"A*")
A11: Acquirers with a meeting booked or later | B11: =COUNTIF(Acquirers!Q2:Q100,"Meeting*")+COUNTIF(Acquirers!Q2:Q100,"NDA*")+COUNTIF(Acquirers!Q2:Q100,"Offer*")
A12: Agencies on the Sept 19 target list | B12: =COUNT(Targets!A2:A200)
A15: HOW THE AUTOMATION WORKS
A16: 1. Plan tab = the master schedule (ET). The same tasks are in TTS_Sale_Plan_Proton.ics (import into Proton Calendar) and tasks.json (feeds the 7:00 AM daily email).
A17: 2. Daily email: tts_daily_digest.py runs on your Mac every morning at 7:00 AM ET through Proton Mail Bridge and sends today's tasks + tomorrow's preview + live numbers.
A18: 3. Status column (Plan, Acquirers): pick from the dropdown. The dashboard above counts it.
A19: 4. Owners: Jim = only you can do it. Jim + Mike = both signatures. Claude Code = runs on your Mac from the sprint prompt. Auto = scheduled, nothing to do.
A21: LEGEND
A22: Blue text = inputs you can change. Black = formulas or fixed text. Yellow fill = verify or fill in. Orange rows on Plan = launch day and offer day.
A24: CONTACT RULES (kept from Sept 19)
A25: Only business contacts from public sources are listed. 'Not published' means no public source was found — the Other routes column gives the legitimate way in (forms, LinkedIn, Impressum, Companies House, state registries). No personal numbers or home addresses, by design.
A26: Canada (ManyVids): no cold email under CASL — LinkedIn or phone only. UK/EU: B2B email with a clear identity and opt-out. US: CAN-SPAM footer with the LLC postal address.
A28: WHAT CHANGED IN V2 (SEPT 25)
A29: Corrected against the overnight onchain verification: the token is immutable (not a proxy), supply is governed by the 2-of-2 Safe, no blacklist is possible, the timelock is a closing-day option rather than executed, and there is no paid audit before an offer. New tasks T66-T75 (WordPress fixes, Bridge password, footer address, audit-finding map, LINK recovery, replacement-cost sheet, traction push, scanner update, walk-away price). Email 1 and the Strengths, Audit & Liquidity, Data Room and Closing tabs were rewritten to match.
... A32: New tabs: Plan, Acquirers, Sequence, Scripts, Strengths, Platforms, Store Plan, Audit & Liquidity, Data Room, Closing. The old Send Schedule tab is replaced by Plan (sale mode). The Targets tab keeps all agencies for weekly enlistment — every enrolled agency is demand evidence for the sale.

Sheet Plan
A1: ID | B1: Date | C1: Day | D1: Time (ET) | E1: Owner | F1: Workstream | G1: Task | H1: How / detail | I1: Status | J1: Done on | K1: Notes
A2: T01 | B2: 46289 | C2: =TEXT(B2,"ddd") | D2: 20:00 | E2: Jim | F2: OPS | G2: Turn on Telegram two-step verification | H2: On the Telegram account that owns @TemptationTokenBot and the channels: Settings > Privacy & Security > Two-Step Verification. Starts the 7-day clock Telegram requires before a bot can change owners. Do not change the password afterward. | I2: Not started
A3: T02 | B3: 46289 | C3: =TEXT(B3,"ddd") | D3: 20:15 | E3: Jim | F3: LEGAL | G3: Send Mike the member consent + Safe-signer agreement | H3: Written consent to sell (assets or the LLC) plus his agreement to sign the Safe transfer at close. Checklist: Data Room tab. | I3: Not started
A4: T03 | B4: 46289 | C4: =TEXT(B4,"ddd") | D4: 21:00 | E4: Jim | F4: OPS | G4: Paste the Claude Code sprint prompt and let it run overnight | H4: File: TTS_Sale_Sprint_ClaudeCode.md. Opens the site to crawlers, generates the AI Models batch, fork-tests the liquidity move, runs the pre-audit, installs the daily reminder email. | I4: Not started
A5: T04 | B5: 46290 | C5: =TEXT(B5,"ddd") | D5: 07:00 | E5: Auto | F5: OPS | G5: First daily digest email arrives | H5: Starts once the Bridge password is in .env (T67). Then every day at 7:00 AM ET through Nov 6. | I5: Not started
A6: T66 | B6: 46290 | C6: =TEXT(B6,"ddd") | D6: 07:30 | E6: Jim | F6: SITE | G6: Fix the 7 false claims on WordPress - '45% APR' first | H6: Replacement text: outputs/site/false_claims_2026-09-25.md. Edit each page by hand in WP admin / Elementor (revision-safe). If a page takes more than 5 minutes, set it to Draft until it's fixed. | I6: Not started
A7: T67 | B7: 46290 | C7: =TEXT(B7,"ddd") | D7: 08:00 | E7: Jim | F7: OPS | G7: Put the Proton Bridge password into .env | H7: Bridge app > your account > copy the Bridge password (not your Proton login) into Claude Code's masked prompt. Unblocks the daily email, the canary and all outreach. | I7: Not started
A8: T68 | B8: 46290 | C8: =TEXT(B8,"ddd") | D8: 08:15 | E8: Jim | F8: LEGAL | G8: Choose the postal address for TTS email footers | H8: CAN-SPAM needs a valid postal address. A USPS P.O. box or a virtual mailbox for Blockchain Entertainment LLC keeps your home and other businesses off TTS mail. Give it to Claude Code. | I8: Not started
A9: T05 | B9: 46290 | C9: =TEXT(B9,"ddd") | D9: 08:30 | E9: Jim | F9: STORE | G9: Check Google Play account type | H9: Play Console > Settings > Developer account > Account details. Personal (created after Nov 13, 2023) = 14-day closed test with 12+ testers first. Organization = submit to production now. Tell Claude Code which. | I9: Not started
A10: T06 | B10: 46290 | C10: =TEXT(B10,"ddd") | D10: 09:00 | E10: Jim | F10: AUDIT | G10: Optional: SolidProof quote request (quote only - no money before an offer) | H10: The draft with disclosures is in outputs/sale/. A quote gives you a 'cost to certify' number for negotiation; fund an audit only if a serious buyer asks for one as a closing condition. | I10: Not started
A11: T07 | B11: 46290 | C11: =TEXT(B11,"ddd") | D11: 09:30 | E11: Jim | F11: LIQ | G11: Transak: generate the PRODUCTION API key | H11: Business verification is done, so pull the production key in the Transak dashboard and hand it to Claude Code through its secure prompt (never paste keys in chat). | I11: Not started
A12: T08 | B12: 46290 | C12: =TEXT(B12,"ddd") | D12: 10:00 | E12: Jim | F12: AI | G12: Create an image-generation API key | H12: Replicate, fal.ai or OpenAI. Add IMAGE_API_KEY to the repo .env. Costs pennies per image. | I12: Not started
A13: T69 | B13: 46290 | C13: =TEXT(B13,"ddd") | D13: 11:00 | E13: Claude Code | F13: AUDIT | G13: Map the original audit's 1 critical + 3 high to the deployed code | H13: Each one: fixed / not applicable / live. Anything live and exploitable = no card go-live until it's mitigated. Results go on /audit. | I13: Not started
... A54: T43 | B54: 46304 | C54: =TEXT(B54,"ddd") | D54: 09:00 | E54: Jim | F54: STORE | G54: Personal Play account: closed test hits 14 days - apply for production | H54: Answers: outputs/listings/play_production_answers.md. | I54: Not started
A55: T44 | B55: 46304 | C55: =TEXT(B55,"ddd") | D55: 12:00 | E55: Jim | F55: AUDIT | G55: Check SolidProof status; answer any questions same day | I55: Not started
A56: T45 | B56: 46307 | C56: =TEXT(B56,"ddd") | D56: 07:00 | E56: Auto | F56: AI | G56: AI Models rotation #3 | H56: Automatic after settlement. | I56: Not started
A57: T46 | B57: 46307 | C57: =TEXT(B57,"ddd") | D57: 09:05 | E57: Auto | F57: OUTREACH | G57: Email 3 ('offers reviewed Friday') to AROA + RCI IR | H57: Jim sends the same note via LinkedIn/forms at 10:00. | I57: Not started
A58: T47 | B58: 46308 | C58: =TEXT(B58,"ddd") | D58: 10:00 | E58: Jim | F58: DATA | G58: Open the data room to every buyer who signed the NDA | H58: Track who opened what - interest signal. | I58: Not started
A59: T48 | B59: 46309 | C59: =TEXT(B59,"ddd") | D59: 12:00 | E59: Claude Code | F59: AUDIT | G59: Refresh the /audit status table (every finding vs. the deployed code) | H59: Replaces the 'publish a new audit' step - no pre-sale audit purchase. | I59: Not started
A60: T49 | B60: 46310 | C60: =TEXT(B60,"ddd") | D60: 17:00 | E60: Jim | F60: OUTREACH | G60: Last-call note to engaged buyers | H60: 'Reviewing offers tomorrow at 5 PM ET.' | I60: Not started
A61: T50 | B61: 46311 | C61: =TEXT(B61,"ddd") | D61: 17:00 | E61: Jim + Mike | F61: CLOSE | G61: OFFERS REVIEW | H61: Rank by total value, cash at close, earn-out terms, certainty, speed. Best structure beats biggest headline. | I61: Not started
A62: T51 | B62: 46314 | C62: =TEXT(B62,"ddd") | D62: 07:00 | E62: Auto | F62: AI | G62: AI Models rotation #4 | H62: Automatic after settlement. | I62: Not started
A63: T52 | B63: 46314 | C63: =TEXT(B63,"ddd") | D63: 10:00 | E63: Jim | F63: CLOSE | G63: Counter/accept, sign the LOI, engage the lawyer | H63: Asset purchase vs. LLC purchase per CPA advice. | I63: Not started
A64: T53 | B64: 46316 | C64: =TEXT(B64,"ddd") | D64: 10:00 | E64: Jim | F64: CLOSE | G64: Open escrow; buyer deposit | I64: Not started
A65: T54 | B65: 46318 | C65: =TEXT(B65,"ddd") | D65: 10:00 | E65: Jim | F65: CLOSE | G65: Buyer diligence Q&A session | H65: Data room + live walkthrough. | I65: Not started
A66: T55 | B66: 46320 | C66: =TEXT(B66,"ddd") | D66: 09:00 | E66: Jim | F66: OPS | G66: Clock change: UK/EU fell back - London is ET+4 until Nov 1 | I66: Not started
A67: T56 | B67: 46321 | C67: =TEXT(B67,"ddd") | D67: 07:00 | E67: Auto | F67: AI | G67: AI Models rotation #5 | H67: Automatic after settlement. | I67: Not started
A68: T57 | B68: 46321 | C68: =TEXT(B68,"ddd") | D68: 10:00 | E68: Claude Code | F68: CLOSE | G68: Transfer rehearsal on a fork | H68: Safe owner swap, role moves, bot transfer checklist, project transfers - dry run. | I68: Not started
A69: T58 | B69: 46323 | C69: =TEXT(B69,"ddd") | D69: 10:00 | E69: Jim + Mike | F69: CLOSE | G69: Sign the purchase agreement | I69: Not started
A70: T59 | B70: 46327 | C70: =TEXT(B70,"ddd") | D70: 09:00 | E70: Jim | F70: OPS | G70: Clock change: US fell back - all times now EST | I70: Not started
A71: T60 | B71: 46328 | C71: =TEXT(B71,"ddd") | D71: 07:00 | E71: Auto | F71: AI | G71: AI Models rotation #6 (skip if closed) | I71: Not started
A72: T61 | B72: 46328 | C72: =TEXT(B72,"ddd") | D72: 10:00 | E72: Jim | F72: CLOSE | G72: Escrow funded - start transfers per the runbook | H72: Closing tab, in order. | I72: Not started
A73: T62 | B73: 46329 | C73: =TEXT(B73,"ddd") | D73: 10:00 | E73: Jim + Mike | F73: CLOSE | G73: Transfers day 1: Safe owner swap + roles + treasury to buyer wallets | H73: Onchain moves only - never hand over keys or seed phrases. | I73: Not started
A74: T63 | B74: 46330 | C74: =TEXT(B74,"ddd") | D74: 10:00 | E74: Jim | F74: CLOSE | G74: Transfers day 2: domains, hosting, repo, cloud projects, Expo/Play, Telegram bot | I74: Not started
A75: T64 | B75: 46331 | C75: =TEXT(B75,"ddd") | D75: 10:00 | E75: Claude Code | F75: CLOSE | G75: Rotate every key and secret; verify buyer controls everything | I75: Not started
A76: T65 | B76: 46332 | C76: =TEXT(B76,"ddd") | D76: 12:00 | E76: Jim | F76: CLOSE | G76: Buyer confirms receipt - escrow releases funds | H76: Sale closed. | I76: Not started

Sheet Acquirers
A1: ID | B1: Tier | C1: Company | D1: Category | E1: HQ / time zone | F1: Decision-maker(s) (public) | G1: Title | H1: Verified business contact (published) | I1: Other routes | J1: Visit / in person | K1: Why they buy (strength framing) | L1: Opening hook | M1: Structure to lead with | N1: Outreach law | O1: Source(s) | P1: Verified? | Q1: Status | R1: Next step | S1: Next date
A2: A1 | B2: 1 | C2: Fanvue | D2: Fan platform - AI-creator category leader | E2: London (Canary Wharf) - ET+5 until Oct 25, then ET+4 until Nov 1 | F2: Will Monange; Harry Fitzgerald; Joel Morris | G2: Co-founder & CEO; Co-founder & COO; Co-founder | H2: Business email not published in the sources checked | I2: LinkedIn (all three founders); fanvue.com business contact; public developer API (integration angle) | J2: London HQ by appointment; XBIZ LA Jan 7-10, 2027 | K2: Built its growth on AI creators and runs the Miss AI pageant - TTS is a weekly onchain fan vote with a disclosed AI Models division next to verified creators, ready to plug into Fanvue's public API. | L2: Miss AI proved fans will vote on AI creators. We run that vote every week, onchain, with an AI Models division beside verified creators. | M2: Cash + earn-out tied to creators onboarded; or tech acquisition + 60-day consulting | N2: UK PECR B2B: identify yourself, give an opt-out | O2: BusinessWire Jan 12 2026 (Series A, founders' titles); Las Vegas Sun Jul 10 2026 ($200M run rate, CEO); Wikipedia/Fanvue (AI creators, Miss AI, public API 2025) | P2: Names/titles: yes. Email/phone: not published | Q2: Not contacted
A3: A2 | B3: 1 | C3: Creators Inc | D3: OnlyFans management agency - largest roster found | E3: Miami, FL - ET | F3: Andrew (Andy) Bachman | G3: Founder & CEO | H3: Not published (site uses a contact form) | I3: creatorsinc.com/contact form; Instagram @creatorsinc; weekly podcast (guest pitch); FL Sunbiz for the principal address (direct mail) | J3: Miami Swim Week - CI Swimwear show (late May/early June) | K3: 400+ creators. Owning the vote means owning a weekly traffic event for the entire roster instead of renting attention. | L3: Your roster is the biggest audience in the category. The platform that turns it into a weekly event is built and running. | M3: Cash + earn-out; or equity partnership | N3: US CAN-SPAM | O3: Sept 19 workbook (creatorsinc.com; Supercreator directory) | P3: Name/title: yes. Email: not published | Q3: Not contacted
A4: A3 | B4: 1 | C4: AROA Agency | D4: OnlyFans management agency (multi-country) | E4: Miami, FL (HQ) - ET | F4: Not published - ask office@ for the partnerships lead by name | G4: - | H4: office@aroaagency.com (site footer, verified Sept 2026); 8101 Biscayne Blvd, Ph 703-24, Miami, FL 33138 | I4: Telegram t.me/aroaagency1; aroaagency.com/uk/contact | J4: XBIZ / AVN (attends) | K4: Refer-Creators program = referral economics; TTS pays referral rewards onchain every week across a multilingual roster. | L4: Your Refer-Creators program already runs on referral economics - this runs it onchain, weekly, for every creator you place. | M4: Cash + earn-out | N4: US CAN-SPAM | O4: aroaagency.com/uk (Sept 19 verification) | P4: Email + address: yes | Q4: Not contacted
A5: A4 | B5: 1 | C5: Infloww | D5: Agency software (OnlyFans CRM) moving into AI + fintech | E5: London - ET+5 until Oct 25 | F5: Not published - UK Companies House lists the directors | G5: Director(s) | H5: Not published | I5: infloww.com contact; Companies House officer search; LinkedIn | J5: - | K5: Diversifying into AI tools and fintech - TTS is a finished fan-engagement + payments layer its agency customers can switch on. | L5: You're building into AI and fintech. Here's a finished engagement-and-payments layer your agencies could turn on next month. | M5: Cash acquisition of the engine + optional revenue share | N5: UK PECR B2B | O5: Company profile (London private limited, founded 2019, ~45 staff); WebCatalog (AI + fintech diversification) | P5: Company facts: yes. Decision-maker: look up | Q5: Not contacted
A6: A5 | B6: 1 | C6: Supercreator (supercreator.app) | D6: Agency software + global agency directory | E6: Tel Aviv - ET+7 | F6: Co-founders Yuval and Amir (surnames not published in sources found) | G6: Co-founders | H6: Not published | I6: Telegram t.me/supercreator_app; X @Supercreatorapp; consultation Calendly on supercreator.app | J6: - | K6: Their directory is the global agency list - TTS becomes a perk they hand every listed agency, or a product they own outright. | L6: Your directory is where agencies live. This is a weekly traffic engine you could hand every one of them. | M6: Cash + rev share on agencies onboarded | N6: B2B with opt-out | O6: Startup registry profile (founded 2022, Tel Aviv); Sept 19 workbook (channels) | P6: Channels: yes. Full names: no | Q6: Not contacted
A7: A6 | B7: 1 | C7: RCI Hospitality Holdings (NASDAQ: RICK) | D7: Public club operator (60+ locations) | E7: Houston, TX - ET-1 | F7: Eric Langan | G7: Chairman, President & CEO | H7: Media & investor contacts (published Nov 2025): Gary Fishman & Michael Wichman, 212-883-0655, gfishman@pondel.com, mwichman@pondel.com | I7: X @RCIHHinc; LinkedIn (Langan) | J7: Rick's Cabaret New York, 50 W 33rd St, NYC (business venue) | K7: 60+ venues whose customers want to be seen; the /clubs flow lets any venue run its own weekly fan vote from a phone - fan engagement that drives door traffic. | L7: Your venues already sell the experience of being seen. This lets every club run a weekly fan vote from a phone and send fans back through the door. | M7: Cash; or license + pilot across 5 venues | N7: US CAN-SPAM | O7: BusinessWire Nov 14 2025 (contacts; Langan title); RCI release Jan 2023 (60+ locations) | P7: IR contacts: yes | Q7: Not contacted
A8: A7 | B8: 2 | C8: The Clueless | D8: AI-model agency (creator of Aitana Lopez) | E8: Barcelona - ET+6 | F8: Ruben Cruz | G8: Co-founder & Creative Director | H8: Not published in sources checked | I8: theclueless.ai contact; LinkedIn | J8: - | K8: Runs AI talent that already earns on Fanvue - an AI Models division needs exactly their roster, and owning the stage beats renting it. | L8: Aitana showed AI talent can build a real audience. We built the weekly stage where fans vote for it. | M8: Cash or equity swap | N8: EU GDPR B2B legitimate interest | O8: Wikipedia/Aitana Lopez; Reason.Why (Cruz title); press on Fanvue presence | P8: Name/title: yes | Q8: Not contacted
A9: A8 | B9: 2 | C9: Fansly | D9: Fan platform (bootstrapped) | E9: Baltimore, MD (Select Media LLC) / Cyprus (CY Media LTD) - ET | F9: Michael Etelis | G9: Founder / owner | H9: Not published | I9: Maryland business registry (Select Media LLC address) for direct mail; LinkedIn; fansly.com business contact | J9: - | K9: Competes on creator features - a weekly spotlight that sends fans to creators' pages is a feature they can ship next week. | L9: Fansly grew by giving creators a better home. This gives them a weekly spotlight that sends fans straight to their page. | M9: Cash acquisition | N9: US CAN-SPAM | O9: Wikipedia/Fansly; MEL Magazine (ownership) | P9: Name: yes. Contact: not published | Q9: Not contacted
A10: A9 | B10: 2 | C10: ManyVids | D10: Creator platform | E10: Montreal - ET | F10: Bella French | G10: Co-founder (CEO title per Wikipedia infobox; verify current title) | H10: Not published | I10: LinkedIn; corporate phone if published on their site | J10: - | K10: Creator-first brand - a weekly fan-vote contest is an engagement feature that fits their residuals story. | L10: You built ManyVids around fair pay for creators. This adds a weekly fan vote that pays creators in attention. | M10: Cash acquisition | N10: Canada CASL - NO cold email. LinkedIn or phone only | O10: Wikipedia/ManyVids | P10: Name: yes | Q10: Not contacted
A11: A10 | B11: 1 | C11: Acquire.Fi | D11: Web3 M&A marketplace (venue + buyer network) | E11: Remote / BVI | F11: Nassim Bouslama; Jan Strandberg | G11: Co-founder & CEO; Co-founder & CTO | H11: Seller form on acquire.fi | I11: X @Acquire_Fi; LinkedIn | J11: - | K11: Web3 buyers who want a working onchain product with apps, entity and distribution - not a whitepaper. | L11: - | M11: Listed ask: $95K structured / $65K all-cash | N11: - | O11: CoinDesk profile (founders); G2 (marketplace scope) | P11: Names: yes | Q11: Not contacted
A12: A11 | B12: 2 | C12: Louna's Models | D12: Agency - runs the Exclu Awards | E12: Los Angeles - ET-3 | F12: Louna | G12: Founder | H12: Not published | I12: Instagram DM | J12: Exclu Awards LA | K12: Owns an awards event - a TTS-powered fan-vote award category turns into ownership of the vote itself. | L12: Exclu Awards is the closest thing to what we run every week - except our vote is onchain. | M12: Cash + partnership | N12: US CAN-SPAM | O12: Sept 19 workbook | P12: Name: yes | Q12: Not contacted
A13: A12 | B13: 2 | C13: Upbrand | D13: Agency (Australia) | E13: Australia - ET+14 (ET+15 after Oct 4) | F13: Tony Izzet | G13: Founder | H13: Not published | I13: Instagram @tonyizzet | J13: - | K13: Capacity-constrained ('all spots filled') - a self-running engine adds revenue without headcount. | L13: Your bio says every spot is filled. This adds revenue per creator without adding a single hire. | M13: Cash + earn-out | N13: Australia Spam Act | O13: Sept 19 workbook (Instagram) | P13: Name: yes | Q13: Not contacted
A14: A13 | B14: 2 | C14: SheX Agency | D14: Agency (DACH, multi-platform) | E14: Germany - ET+6 | F14: Named in the Impressum (verify at she-x.de/impressum) | G14: Geschaeftsfuehrer | H14: Impressum email (legally required - Claude Code verifies before sending) | I14: Instagram @onlyfans_agentur | J14: - | K14: Runs creators across several platforms, so off-platform promotion is already their model. | L14: You already run creators across five platforms - this is the one that brings fans to all of them. | M14: Cash + earn-out | N14: EU GDPR B2B | O14: Sept 19 workbook (Trustpilot, Instagram) | P14: Route: yes | Q14: Not contacted
A16: Tier 1 count | B16: =COUNTIF(B2:B14,1)
A17: Tier 2 count | B17: =COUNTIF(B2:B14,2)
A18: Structure note: list the full package at $95K structured (cash + earn-out) or $65K all-cash. The gap nudges buyers toward structure. Never lead with token price. Your private floor stays off every document.

Sheet Sequence
A1: Acquirer ID | B1: Company | C1: Date | D1: Day | E1: Time (ET) | F1: Channel | G1: Action | H1: Script (Scripts tab) | I1: Status
A2: A13 | B2: SheX Agency | C2: 46296 | D2: =TEXT(C2,"ddd") | E2: 03:05 | F2: Email (auto) | G2: Email 1 to the verified Impressum address (9:05 Berlin) | H2: Email 1 - acquirer | I2: Not started
A3: A3 | B3: AROA Agency | C3: 46296 | D3: =TEXT(C3,"ddd") | E3: 09:05 | F3: Email (auto) | G3: Email 1 to office@aroaagency.com | H3: Email 1 - acquirer | I3: Not started
A4: A6 | B4: RCI Hospitality Holdings (NASDAQ: RICK) | C4: 46296 | D4: =TEXT(C4,"ddd") | E4: 09:05 | F4: Email (auto) | G4: Email 1 to gfishman@pondel.com + mwichman@pondel.com | H4: Email 1 - acquirer | I4: Not started
A5: A10 | B5: Acquire.Fi | C5: 46296 | D5: =TEXT(C5,"ddd") | E5: 09:30 | F5: Listing form | G5: Submit the Acquire.Fi seller form | I5: Not started
A6: A1 | B6: Fanvue | C6: 46296 | D6: =TEXT(C6,"ddd") | E6: 10:00 | F6: Web form | G6: Email 1 + Fanvue hook via fanvue.com business contact | H6: Email 1 - acquirer | I6: Not started
A7: A2 | B7: Creators Inc | C7: 46296 | D7: =TEXT(C7,"ddd") | E7: 10:00 | F7: Web form | G7: Email 1 via creatorsinc.com/contact | H7: Email 1 - acquirer | I7: Not started
A8: A4 | B8: Infloww | C8: 46296 | D8: =TEXT(C8,"ddd") | E8: 10:00 | F8: Web form | G8: Email 1 via infloww.com contact | H8: Email 1 - acquirer | I8: Not started
A9: A7 | B9: The Clueless | C9: 46296 | D9: =TEXT(C9,"ddd") | E9: 10:00 | F9: Web form | G9: Email 1 via theclueless.ai | H9: Email 1 - acquirer | I9: Not started
A10: A1 | B10: Fanvue | C10: 46296 | D10: =TEXT(C10,"ddd") | E10: 10:30 | F10: LinkedIn | G10: Connect note to Monange, Fitzgerald, Morris | H10: LinkedIn connection note | I10: Not started
A11: A2 | B11: Creators Inc | C11: 46296 | D11: =TEXT(C11,"ddd") | E11: 10:30 | F11: LinkedIn | G11: Connect note to Andy Bachman | H11: LinkedIn connection note | I11: Not started
A12: A4 | B12: Infloww | C12: 46296 | D12: =TEXT(C12,"ddd") | E12: 10:30 | F12: LinkedIn | G12: Connect note to directors found on Companies House | H12: LinkedIn connection note | I12: Not started
A13: A6 | B13: RCI Hospitality Holdings (NASDAQ: RICK) | C13: 46296 | D13: =TEXT(C13,"ddd") | E13: 10:30 | F13: LinkedIn | G13: Connect note to Eric Langan | H13: LinkedIn connection note | I13: Not started
A14: A7 | B14: The Clueless | C14: 46296 | D14: =TEXT(C14,"ddd") | E14: 10:30 | F14: LinkedIn | G14: Connect note to Ruben Cruz | H14: LinkedIn connection note | I14: Not started
A15: A8 | B15: Fansly | C15: 46296 | D15: =TEXT(C15,"ddd") | E15: 10:30 | F15: LinkedIn | G15: Connect note to Michael Etelis | H15: LinkedIn connection note | I15: Not started
A16: A9 | B16: ManyVids | C16: 46296 | D16: =TEXT(C16,"ddd") | E16: 10:30 | F16: LinkedIn | G16: Connect note to Bella French (no cold email - CASL) | H16: LinkedIn connection note | I16: Not started
A17: A10 | B17: Acquire.Fi | C17: 46296 | D17: =TEXT(C17,"ddd") | E17: 12:30 | F17: X | G17: DM @Acquire_Fi with the one-pager link | H17: DM | I17: Not started
... A22: A8 | B22: Fansly | C22: 46297 | D22: =TEXT(C22,"ddd") | E22: 10:00 | F22: Web form | G22: Email 1 via fansly.com business contact | H22: Email 1 - acquirer | I22: Not started
A23: A3 | B23: AROA Agency | C23: 46297 | D23: =TEXT(C23,"ddd") | E23: 12:30 | F23: Telegram | G23: Nudge on t.me/aroaagency1 + Loom | I23: Not started
A24: A13 | B24: SheX Agency | C24: 46301 | D24: =TEXT(C24,"ddd") | E24: 03:05 | F24: Email (auto) | G24: Email 2 | H24: Email 2 - proof | I24: Not started
A25: A3 | B25: AROA Agency | C25: 46301 | D25: =TEXT(C25,"ddd") | E25: 09:05 | F25: Email (auto) | G25: Email 2 (proof + data room) | H25: Email 2 - proof | I25: Not started
A26: A6 | B26: RCI Hospitality Holdings (NASDAQ: RICK) | C26: 46301 | D26: =TEXT(C26,"ddd") | E26: 09:05 | F26: Email (auto) | G26: Email 2 (proof + data room) | H26: Email 2 - proof | I26: Not started
A27: A1 | B27: Fanvue | C27: 46301 | D27: =TEXT(C27,"ddd") | E27: 10:00 | F27: LinkedIn | G27: Email 2 (proof + data room) to accepted connections | H27: Email 2 - proof | I27: Not started
A28: A10 | B28: Acquire.Fi | C28: 46301 | D28: =TEXT(C28,"ddd") | E28: 10:00 | F28: Email / X | G28: Follow-up with Loom + audit status | I28: Not started
A29: A2 | B29: Creators Inc | C29: 46301 | D29: =TEXT(C29,"ddd") | E29: 10:00 | F29: IG / LinkedIn | G29: Email 2 (proof + data room) | H29: Email 2 - proof | I29: Not started
A30: A4 | B30: Infloww | C30: 46301 | D30: =TEXT(C30,"ddd") | E30: 10:00 | F30: LinkedIn | G30: Email 2 (proof + data room) | H30: Email 2 - proof | I30: Not started
A31: A5 | B31: Supercreator (supercreator.app) | C31: 46301 | D31: =TEXT(C31,"ddd") | E31: 10:00 | F31: Telegram | G31: Email 2 content (proof + data room) | H31: Email 2 - proof | I31: Not started
A32: A7 | B32: The Clueless | C32: 46301 | D32: =TEXT(C32,"ddd") | E32: 10:00 | F32: LinkedIn | G32: Email 2 (proof + data room) | H32: Email 2 - proof | I32: Not started
A33: A8 | B33: Fansly | C33: 46301 | D33: =TEXT(C33,"ddd") | E33: 10:00 | F33: LinkedIn | G33: Email 2 (proof + data room) | H33: Email 2 - proof | I33: Not started
A34: A9 | B34: ManyVids | C34: 46301 | D34: =TEXT(C34,"ddd") | E34: 10:00 | F34: LinkedIn | G34: Email 2 content via message | H34: Email 2 - proof | I34: Not started
A35: A11 | B35: Louna's Models | C35: 46301 | D35: =TEXT(C35,"ddd") | E35: 12:30 | F35: Instagram | G35: Proof DM with Loom | H35: DM | I35: Not started
A36: A12 | B36: Upbrand | C36: 46301 | D36: =TEXT(C36,"ddd") | E36: 12:30 | F36: Instagram | G36: Proof DM with Loom | H36: DM | I36: Not started
A37: A6 | B37: RCI Hospitality Holdings (NASDAQ: RICK) | C37: 46302 | D37: =TEXT(C37,"ddd") | E37: 10:30 | F37: Phone | G37: Call IR at 212-883-0655 - ask who evaluates digital deals | H37: Call opener | I37: Not started
A38: A6 | B38: RCI Hospitality Holdings (NASDAQ: RICK) | C38: 46303 | D38: =TEXT(C38,"ddd") | E38: 18:00 | F38: Visit (optional) | G38: Rick's Cabaret New York - GM demo + corporate intro | H38: Club visit | I38: Not started
A39: A13 | B39: SheX Agency | C39: 46307 | D39: =TEXT(C39,"ddd") | E39: 03:05 | F39: Email (auto) | G39: Email 3 | H39: Email 3 - offer date | I39: Not started
A40: A3 | B40: AROA Agency | C40: 46307 | D40: =TEXT(C40,"ddd") | E40: 09:05 | F40: Email (auto) | G40: Email 3 - offers reviewed Oct 16 | H40: Email 3 - offer date | I40: Not started
... A47: A8 | B47: Fansly | C47: 46307 | D47: =TEXT(C47,"ddd") | E47: 10:00 | F47: LinkedIn | G47: Email 3 - offers reviewed Oct 16 | H47: Email 3 - offer date | I47: Not started
A48: A9 | B48: ManyVids | C48: 46307 | D48: =TEXT(C48,"ddd") | E48: 10:00 | F48: LinkedIn | G48: Offers reviewed Oct 16 | I48: Not started
A49: A1 | B49: Fanvue | C49: 46310 | D49: =TEXT(C49,"ddd") | E49: 17:00 | F49: LinkedIn | G49: Last call (if engaged) | H49: Call opener | I49: Not started

Sheet Scripts
A1: Script | B1: Text (fill {{FirstName}}, {{Company}}, {{Hook}} from the Acquirers tab) | C1: Verified 2026-09-25 (Claude Code)
A2: Email 1 - acquirer (Oct 1) | B2: Subject A: Acquisition: a working onchain fan-voting platform Subject B: {{Company}} + a weekly fan-vote engine you could own Hi {{FirstName}}, {{Hook}} I'm Jim Goetz, founder of Temptation Token. We built a complete weekly fan-voting platform on Base: fans vote for creators, winners receive onchain trophies, and every creator's profile sends voters straight to her link hub. Working today: - Web app, Android app, Telegram bot - Face ID sign-up with gas-free wallets; card purchases through Transak - Weekly rounds that settle themselves onchain - every vote and winner publicly verifiable - Club self-serve onboarding, referral engine, automated social posting - An AI Models division, clearly labeled, ready for agency creators to join - Contracts verified on Base: supply governed by a 2-of-2 multisig, no blacklist function, full audit history disclosed - Delaware entity, domains, brand, and an SEO site that publishes automatically My other companies need my full attention, so Temptation Token needs a full-time owner. We're reviewing offers on Friday, October 16. If owning it makes sense for {{Company}}, I'll open the data room under NDA - 20 minutes is enough to see it live: calendly.com/temptationtoken/phone-meeting Jim Goetz Founder, Temptation Token - Blockchain Entertainment LLC jim@temptationtoken.io | C2: [HOLDS] Trophies, onchain settlement and the profile link-out all verified.
A3: Email 2 - proof (Oct 6) | B3: Subject: 2-minute walkthrough + data room - Temptation Token {{FirstName}} - here's the platform running live: [LOOM_URL] New since last week: [SHIPPED_THIS_WEEK - e.g. card purchases live, deeper liquidity, audit underway, Round # settled] The data room covers contracts, round history, metrics, architecture, monthly running cost, and the transfer runbook. Reply 'NDA' and I'll send it today. Offers are reviewed Friday, October 16. Jim | C3: [FIX] "audit underway" is NOT true — the SolidProof contact is quote-only by decision. Replace that example. Also: the data room's monthly cost sheet needs real invoice figures and the transfer runbook is a draft — finish both before Oct 6 or drop them from the sentence.
A4: Email 3 - offer date (Oct 12) | B4: Subject: Offers reviewed Friday - Temptation Token {{FirstName}} - a quick note that we're reviewing offers this Friday, October 16 at 5 PM ET. Cash, cash plus earn-out, and partnership structures are all on the table. If a 20-minute look would help before then: calendly.com/temptationtoken/phone-meeting Jim | C4: [HOLDS] No factual claims to check.
A5: LinkedIn connection note (300 chars max) | B5: Jim Goetz, founder of Temptation Token - a working onchain fan-voting platform (web, Android, Telegram). We're reviewing acquisition offers Oct 16 and {{Company}} is a natural fit. Worth a 20-minute look? | C5: [NEEDS EDIT] "(web, Android, Telegram)" — no Android build is published. Say "web and Telegram, Android in progress."
A6: DM - Instagram / X / Telegram | B6: {{FirstName}} - Jim Goetz, founder of Temptation Token. We built a weekly onchain fan vote: creators get a spotlight, fans vote, winners get trophies, and every profile sends fans to the creator's page. We're selling it to an owner with a roster - {{Company}} fits. Can I send the 2-minute walkthrough? | C6: [HOLDS] Mechanic described accurately.
A7: Call opener - RCI investor relations (Oct 7) | B7: [STRUCK 2026-09-25 — see verification note] Hi Gary, Jim Goetz, founder of Temptation Token. I emailed you and Michael last week. We're selling a turnkey fan-engagement platform with a self-serve club program - any venue can run its own weekly fan vote from a phone. Who at RCI looks at digital partnerships or acquisitions? I'd like to get them a 20-minute demo before we review offers on the 16th. | C7: [STRUCK] "self-serve club program — any venue can run its own weekly fan vote from a phone" is FALSE. Club registration is admin-only (requireAdmin on every write in api/set-club-wallet.js); pending_clubs and club_partners both have 0 rows. USE INSTEAD: "a club partner program wired on-chain — a club code links to a wallet and its 10% share pays automatically on settlement; registration is approved by us."
A8: Voicemail (20 seconds) | B8: Hi, it's Jim Goetz with Temptation Token - I sent a note about a weekly fan-vote platform we're selling to an owner with a roster or venues. The two-minute walkthrough is in your inbox; my email is jim@temptationtoken.io. We're reviewing offers October 16. Thanks. | C8: [HOLDS] No factual claims to check.
A9: Club visit (60 seconds) | B9: [STRUCK 2026-09-25 — see verification note] Hi, I'm Jim Goetz with Temptation Token. We run a weekly fan vote for entertainers - your club can join from a phone in about two minutes, and it sends fans back through your door. Can I show you on my phone? [Scan the /clubs QR together.] | C9: [STRUCK] "join from a phone in about two minutes" is FALSE for the same reason. Also temptationtoken.io/clubs returns 404, so "[Scan the /clubs QR together]" points at a dead URL — build the page or drop the QR step.
A11: Placeholders | B11: [LOOM_URL] = your demo link. [SHIPPED_THIS_WEEK] = Claude Code fills from live data. Claude Code verifies every line against chain and the live app before Oct 1 and strikes anything that doesn't hold. Never state a prize-pool dollar figure, token price, APR or return. | C11: [NOTE] Verification done 2026-09-25 — see ops/sale/claims_verification_2026-09-25.md.

Sheet Strengths
A1: What a buyer might ask about | B1: The strength (every line true under diligence) | C1: Proof to show | D1: Verified 2026-09-25 (Claude Code)
A2: No revenue yet | B2: Clean slate: no legacy customers, refunds or churn. The buyer sets monetization from day one - sponsored rounds, featured slots, card on-ramp partner fees. | C2: Revenue-lever sheet | D2: [HOLDS] Framing, not a factual claim.
A3: 23 players, 3 votes to date | B3: The buyer is paying for a proven machine at below replacement cost and bringing the audience - so every future vote is theirs. The numbers are stated plainly, which makes every other claim credible. | C3: Replacement-cost sheet; round history | D3: [HOLDS (one phrase pending)] Numbers verified against production 2026-09-25. "Below replacement cost" depends on outputs/sale/data_room/replacement_cost.md — quote its figure rather than the adjective.
A4: Chainlink automation stalled in the past | B4: Self-healing settlement, proven: Rounds 9-12 each settled unattended within 30 minutes of close - four in a row, verifiable onchain. | C4: Basescan settlement txs, Rounds 9-12 | D4: [HOLDS — tighter than claimed] Verified: settlement ran 19.6, 22.4, 17.3 and 18.3 minutes after close for rounds 9-12. PROVE IT FROM CHAIN (round_history.csv), never from admin_audit_log — three of the four SETTLE rows are wrongly recorded no_state_change, which makes the autopilot look worse than it is.
A5: Token contract can't be upgraded | B5: Immutable token: nobody - not us, not the buyer - can change its code. What diligence verifies is what runs forever, and any audit the buyer commissions stays valid permanently. | C5: Empty EIP-1967 slot; bytecode on Basescan | D5: [HOLDS] proxiableUUID() returns instead of reverting; EIP-1967 slot zero; 20,747B of code. Both token and V3d show "Contract Source Code Verified" on BaseScan.
A6: Supply can be expanded | B6: Supply is governed by a 2-of-2 multisig: expansion needs both signatures, so the owner can fund future rewards without a token migration. A 48-hour timelock package is ready to install at close if the buyer wants one. | C6: Role map; timelock package (from Sep 28) | D6: [HOLDS] Executed on a mainnet fork: granted MINTER, minted 1B, supply 69B to 70B. Timelock package is built and fork-tested but NOT executed.
A7: Blacklist concerns from scanners | B7: No blacklist - provably: the contract has no function that can ever freeze an address. | C7: Source: blacklisted mapping has no setter | D7: [NEEDS CAVEAT] Blacklist half VERIFIED — the mapping has no setter, no address can ever be blacklisted. But pause() exists; PAUSER_ROLE has no holders today (verified) and the Safe could grant it, freezing ALL transfers. Say it first: an auditor will. ADD: "A global pause exists; PAUSER_ROLE has no holders and the multisig would have to grant it — the 48h timelock makes that public and delayed."
A8: Zero-value transfers revert | B8: Disclosed up front with its scope: only a transfer of exactly zero tokens is affected. Normal transfers, swaps and the new liquidity route all passed fork tests. | C8: Fork transcript; /audit table | D8: [HOLDS] Scope confirmed on fork: only exactly-zero transfers revert. A 100 TTS taxed transfer delivered 99 TTS correctly.
A9: Old audit claims were wrong | B9: Full audit history disclosed, each finding mapped to the deployed code, and every public claim re-verified against chain and corrected. | C9: /audit status table; original report | D9: [HOLDS once the mapping table ships] The finding-to-bytecode table is being built and will be published on /audit.
A10: Thin liquidity / Blockaid 'spam' label | B10: Deeper liquidity with zero cash outlay: card buys up to $1,000 at 3.26% impact ($500 at 1.92%) once Safe tx #1 executes, funded with 0.0101% of the Safe's TTS. The no-blacklist finding backs the scanner appeal. | C10: Fork measurements; Blockaid update | D10: [HOLDS — add a condition] Fork-measured. Say "once Safe tx #1 executes" every single time; it is not true yet.
A11: Placeholder profiles | B11: [STRUCK 2026-09-25] AI Models division: always-on demo content plus a clearly labeled AI category - the category Fanvue built its growth on with the Miss AI pageant. | C11: Board screenshots; rotation log | D11: [STRUCK] Not built. Zero AI profiles exist, no badge or filter ships in any client, and ops/sale/rotation_log.csv does not exist. Blocked on IMAGE_API_KEY. USE INSTEAD: "Schema and constraints for a labelled AI-model category are deployed; generation and display are not built yet." Do not offer board screenshots or a rotation log as proof.
A12: No iOS App Store listing | B12: [STRUCK 2026-09-25] iPhone users are served through the web app and Telegram - no Apple review gate and no 30% commission. The TestFlight build transfers for a buyer who wants a native route. | C12: PWA install guide; TestFlight build | D12: [STRUCK] "TestFlight build transfers" is false — mobile/eas.json still holds three REPLACE_WITH_* placeholders and there is no Apple Developer account, so no TestFlight build exists. The PWA install guide does not exist either. USE INSTEAD: "The iOS project is configured for TestFlight and needs only an Apple Developer account." The no-review-gate / no-30%-commission points do hold.
... A19: The mechanic is copyable | B19: Time-to-market: build, deployment, apps, entity and distribution groundwork are done - the replacement-cost sheet shows what a buyer skips. | C19: Replacement-cost sheet | D19: [HOLDS once the sheet ships] Depends on outputs/sale/data_room/replacement_cost.md.

Sheet Platforms
A1: Venue | B1: What it is | C1: Role in this sale | D1: Seller cost | E1: Timing | F1: Site | G1: Status
A2: Acquire.Fi | B2: Web3 M&A marketplace for crypto-native businesses | C2: Primary venue | D2: Seller form; selective acceptance | E2: Submit Oct 1 | F2: acquire.fi | G2: Not started
A3: SideProjectors | B3: Free listing, no commission, no escrow | C3: Secondary - fast | D3: Free / 0% | E3: Submit Oct 1 | F3: sideprojectors.com | G3: Not started
A4: IndieMaker | B4: Accepts pre-revenue | C4: Secondary | D4: 3% on pre-revenue (per July 2026 comparison) | E4: Submit Oct 1 | F4: indiemaker.co | G4: Not started
A5: ExitBid | B5: 5-day auction format | C5: Optional - price discovery | D5: $199 flat, 0% (their own comparison - verify) | E5: Optional | F5: exitbid.io | G5: Not started
A6: Flippa | B6: Largest general marketplace | C6: Only with SFW engine framing + agency pilot disclosed, after Flippa confirms eligibility | D6: $49-$499 listing + 5-10% | E6: Ask support first | F6: flippa.com | G6: Not started
A7: Acquire.com | B7: Curated startup marketplace | C7: After first revenue (pre-revenue only for SaaS/AI) | D7: Monthly listing fee + closing commission | E7: Later | F7: acquire.com | G7: Not started
A8: Microns | B8: Profitable micro-startups | C8: Skip (pre-revenue declined) | D8: 6-10% success fee | E8: Skip | F8: microns.io | G8: Not started
A9: Direct outreach | B9: Acquirers tab - the real buyers | C9: Primary | D9: 0% | E9: Oct 1 launch | F9: - | G9: Not started
A10: r/SideProject, r/SaaSforSale | B10: Communities | C10: Check each sub's rules | D10: Free | E10: Oct 1 if allowed | F10: reddit.com | G10: Not started
A11: Base ecosystem | B11: base.dev registration + builder channels | C11: Visibility with Web3 builders | D11: Free | E11: Sep 29 | F11: base.dev | G11: Not started
A13: Notes: Flippa's rules exclude adult businesses including OnlyFans-supporting ones and bar selling accounts on other platforms — use it only if Flippa confirms eligibility for the SFW engine framing with the agency pilot disclosed. Acquire.com accepts pre-revenue listings only for functional SaaS/AI products. Fee figures for IndieMaker/ExitBid/SideProjectors/Flippa come from a July 2026 comparison written by ExitBid — verify on each site.

Sheet Store Plan
A1: Channel | B1: Plan | C1: Timing | D1: Why it's a strength
A2: Android - APK | B2: Live now: direct download link on the homepage | C2: Done / keep | D2: Buyers can install it today
A3: Android - Google Play | B3: Personal account: 14-day closed test with 12+ testers, then apply for production. Organization account: submit now. Listing copy: 'vote for your favorites, win trophies' - declare tokenized assets, no earnings hype. | C3: Start Sep 25 | D3: Live around mid-October if the test starts Sep 25
A4: iPhone - web app (PWA) | B4: Add-to-Home-Screen install guide on the site; full app experience with no store gate | C4: Sep 26 site rebuild | D4: No Apple review, no 30% fee
A5: iPhone - Telegram Mini App | B5: @TemptationTokenBot opens app.temptationtoken.io inside Telegram | C5: Existing path | D5: Crypto-native users stay in Telegram
A6: iOS - App Store | B6: No submission: Apple's guideline 1.2 names 'hot-or-not' voting on real people as not belonging on the App Store. The TestFlight build transfers with the sale for a buyer who wants to pursue a native route. | C6: Not submitting | D6: Keeps the listing asset clean of a rejection record

Sheet Audit & Liquidity
A1: Audit readiness — verified findings on the deployed contracts and how each is disclosed or answered
A2: Contract | B2: Expected finding | C2: Typical category | D2: Mitigation before submission
A3: Token | B3: Governed supply: the Safe can grant itself MINTER_ROLE (proved on a fork: 69B -> 70B) | C3: Centralization - can't be changed (immutable) | D3: Disclosed; 2-of-2 multisig; 48h timelock package ready for the buyer at close
A4: Token | B4: transfer(x, 0) reverts with an arithmetic panic; the recorded M-1 fix never deployed | C4: Low/Medium - can't be changed (immutable) | D4: Disclosed with scope; normal transfers and swaps pass; a buyer can migrate to a v2 token if wanted
A5: Token | B5: Not a proxy - the token is immutable (earlier copy said UUPS) | C5: Informational | D5: App copy corrected; WordPress copy fixed by T66
A6: Token | B6: Blacklist mapping has no setter | C6: Positive finding | D6: Evidence for the Blockaid / GoPlus update (T73)
A7: Token | B7: 1% transfer tax + tax-exemption control | C7: Owner privilege | D7: Disclosed; exempt pools listed
A8: Original SolidProof report | B8: 1 critical + 3 high | C8: Map each to the deployed code | D8: T69 - fixed / not applicable / live; gate before card go-live
A9: TTSVotingV3d | B9: Privileged settlement fallback used by the keeper autopilot | C9: Centralization / informational | D9: Scoped role; settlement log published
A10: TTSVotingV3d | B10: Chainlink VRF subscription must stay funded | C10: Informational | D10: Auto-funder with reserve floor; LINK recovery (T70)
A11: Staking proxy | B11: Upgradeable (a real proxy - reverts correctly) | C11: Centralization | D11: Multisig; timelock option at close
A12: Trophy NFT | B12: Minter role | C12: Low / informational | D12: Held by the voting contract only; document
A14: Audit budget reference (2026 market)
A15: Simple token / NFT | B15: $1,000-$10,000 · 2-8 days
A16: Staking / governance / NFT systems | B16: $5,000-$20,000 · 1-3 weeks
A17: Rush turnaround | B17: +20-50%
A18: Source: QuillAudits, 'Smart Contract Audit Cost 2026' (market ranges). Sept 25 decision: no paid audit before an offer - the token is immutable, so a new report can only restate the two findings that can't change. Get a quote for negotiation; fund one only if a serious buyer makes it a closing condition.
A20: Liquidity + card on-ramp plan (Safe tx #1 built and fork-verified; no cash outlay)
A21: Step | B21: Action | C21: Who signs / runs | D21: Gate
A22: 1 | B22: Safe tx #1 (built + fork-verified): new concentrated pool, setTaxExempt(pool), single-sided position funded with 0.0101% of the Safe's 10B TTS | C22: Jim + Mike sign (T10) | D22: Expires Oct 9 - rebuild if price moves
A23: 2 | B23: Measured result: max card buy ~$50 -> $1,000; $500 at 1.92% impact, $1,000 at 3.26% | C23: Claude Code | D23: Measured by actual swaps on a fork
A24: 3 | B24: App routing: quote V2 + the new pool, route the better price; 5% impact guard stays | C24: Claude Code | D24: Deploy after tx #1 executes
A25: 4 | B25: Map the original audit's critical/high findings to the deployed code | C25: Claude Code (T69) | D25: Gate before any card go-live
A26: 5 | B26: Transak production key into Vercel; card tab on; $30 live test | C26: Jim + Claude Code (T07, T20) | D26: After steps 1 and 4
A27: 6 | B27: Recover ~44 LINK: cancel + withdraw the retired upkeep; VRF to 25+ LINK first; remainder to ETH for sell-side depth | C27: Claude Code builds (T70) | D27: Gate met: Rounds 9-12 settled unattended
A28: 7 | B28: Blockaid / GoPlus update with the no-blacklist evidence + new liquidity | C28: Claude Code drafts, Jim sends (T73) | D28: After tx #1 has run a few days

Sheet Data Room
A1: # | B1: Item | C1: Status | D1: Location / link
A2: 1 | B2: One-pager (asset list, what's live, real numbers, offer date) | C2: Not started
A3: 2 | B3: 2-3 minute Loom demo | C3: Not started
A4: 3 | B4: Contract list with Basescan links (token, TTSVotingV3d, staking proxy, Trophy NFT, Safe) | C4: Not started
A5: 4 | B5: Audit history: original SolidProof report + finding-status table vs. the deployed code + Slither/Aderyn pre-audit | C5: Not started
A6: 5 | B6: Replacement-cost sheet (what it would cost to build this, from git history) | C6: Not started
A7: 6 | B7: Round history export (every round: votes, winner, settlement tx, who settled) | C7: Not started
A8: 7 | B8: Metrics snapshot (players, votes, signups, card buys, pool depth) - real numbers only | C8: Not started
A9: 8 | B9: Architecture doc + CLAUDE.md operating manual | C9: Not started
A10: 9 | B10: Monthly running cost sheet (Vercel, Railway, Supabase, LINK, paymaster, hosting, email) | C10: Not started
A11: 10 | B11: Transfer runbook (Closing tab) + the ready-to-install timelock package | C11: Not started
A12: 11 | B12: Entity pack: Delaware certificate, EIN letter, operating agreement, member consent | C12: Not started
A13: 12 | B13: IP assignment (Jim to Blockchain Entertainment LLC) | C13: Not started
... A17: 16 | B17: Site + SEO: Search Console / Bing data, indexed pages, AnswerPress content library | C17: Not started
B19: Member consent (Mike) — must say: (1) he consents to the sale of Blockchain Entertainment LLC's assets or of the LLC itself; (2) he will sign the Safe owner change and role transfers at close; (3) proceeds split per the operating agreement. Have the lawyer finalize.

Sheet Closing
A1: Asset | B1: How it transfers | C1: Where | D1: Status
A2: Safe | B2: Add the buyer's signers, remove Jim's and Mike's (both sign) | C2: Onchain | D2: Not started
A3: Contract roles | B3: Move admin/upgrader to the buyer's Safe or timelock | C3: Onchain | D3: Not started
A4: Optional timelock | B4: Install the 48-hour timelock package if the buyer wants one | C4: Onchain | D4: Not started
A5: Treasury + ecosystem tokens | B5: Send to wallets the buyer generates | C5: Onchain | D5: Not started
A6: LP positions | B6: Transfer the position NFT / LP tokens (and any lock) to the buyer | C6: Onchain | D6: Not started
A7: Chainlink VRF subscription | B7: Request + accept subscription owner transfer | C7: Onchain | D7: Not started
A8: Keeper autopilot / Bank wallet | B8: Buyer deploys a new Bank key; move balances; revoke old | C8: Onchain + Railway | D8: Not started
A9: Domains | B9: temptationtoken.io (+ any others) push to buyer's registrar account | C9: Registrar | D9: Not started
A10: WordPress + hosting | B10: Hostinger account/site transfer; AnswerPress re-connection | C10: Hosting | D10: Not started
A11: Code | B11: GitHub repo transfer (incl. CLAUDE.md) | C11: GitHub | D11: Not started
A12: Cloud | B12: Vercel, Supabase, Railway project transfers | C12: Each platform | D12: Not started
... A19: Exclude | B19: Unsolicited airdrop tokens in the Bank wallet - never list, never interact | C19: - | D19: Not started
A21: Wallet rule: move assets and roles onchain to wallets the buyer creates. Never hand over private keys or seed phrases — a buyer can never prove a handed-over key wasn't copied, and prices that risk in.

Sheet Scoring Model
A1: Predictive fit model — agency 'yes' likelihood (Sept 19, unchanged)
A2: Score = weighted average of five 0-5 components, scaled to 100. P(meeting) comes from the band table. Both are starting assumptions (blue) — overwrite with your own reply data.
A4: Component | B4: Weight | C4: What 5 means | D4: What 0 means
A5: Scale (roster size / reach) | B5: 0.25 | C5: 100+ creators or 400+ (Creators Inc); one yes = many weekly entrants | D5: Solo operator / a handful of creators
A6: Reachability of decision-maker | B6: 0.25 | C6: Named founder + published business email/Telegram | D6: Anonymous team, intake form only
A7: Openness (crypto / off-platform promo / performance marketing) | B7: 0.2 | C7: Multi-platform, Telegram-native, Dubai/EU, runs traffic ops | D7: OnlyFans-only, discreet/no-face roster, no social promo
A8: Reputation safety (inverse risk) | B8: 0.15 | C8: Clean press, registered company, transparent splits | D8: Active litigation / creator-exploitation coverage
A9: Meet-in-person access | B9: 0.15 | C9: Hosts or attends XBIZ/AVN/Swim Week/own events | D9: No public events
A10: Weight check (must be 100%) | B10: =SUM(B5:B9)
A12: P(meeting) bands — probability an agency books a call after the full sequence
A13: Score floor | B13: P(meeting) | C13: Rationale
A14: 0 | B14: 0.04 | C14: Cold, hard-to-reach, low fit: email-only cold B2B response rates typically sit in low single digits
A15: 50 | B15: 0.09 | C15: Average fit with multi-channel follow-up (email + DM + phone)
A16: 65 | B16: 0.15 | C16: Good fit, reachable decision-maker
A17: 80 | B17: 0.25 | C17: Tier-1 fit + published direct channel or warm intro
A19: Channel multipliers (assumptions — calibrate)
A20: Touch / condition | B20: Multiplier | C20: Note
A21: Warm intro (Rare X Network, Supercreator, a creator already on the board) | B21: 2 | C21: Referral beats cold in every outbound benchmark
A22: Phone follow-up reached a human | B22: 1.5 | C22: Live conversation vs inbox
A23: Met in person at an event | B23: 3 | C23: XBIZ/AVN/Swim Week hallway meeting
A24: Email only, no other channel | B24: 0.6 | C24: Discount the band value if you skip DM + phone

Sheet Targets
A1: # | B1: Agency | C1: HQ / cities | D1: Country | E1: Time zone | F1: Offset vs ET (hrs) | G1: Person in charge (public) | H1: Title | I1: Verified public email | J1: Website / apply / contact | K1: Instagram | L1: X / Telegram / other | M1: Business phone (published) | N1: Business mailing address (published) | O1: Direct-contact route | P1: Roster / scale signal (their claim unless noted) | Q1: Source URL(s) | R1: Tier | S1: Scale (0-5) | T1: Reach (0-5) | U1: Openness (0-5) | V1: Rep safety (0-5) | W1: Meet access (0-5) | X1: Fit score | Y1: P(meeting) | Z1: Send 09:05 local = ET time | AA1: ET day | AB1: In Aug cohort-1? (Y/N) | AC1: Notes / risks / angle | AD1: Sale-track role (Sept 24)
A2: 1 | B2: Creators Inc | C2: Miami, FL (content house; events in Miami & NYC) | D2: USA | E2: America/New_York (EDT) | F2: 0 | G2: Andrew (Andy) Bachman | H2: Founder & CEO | I2: not published | J2: creatorsinc.com/contact (form) · creatorsinc.com/apply | K2: @creatorsinc | L2: YouTube @creatorsinc · weekly podcast hosted by Bachman | M2: not published | N2: Not on site — pull principal address via FL Sunbiz | O2: Founder is highly public (Entrepreneur, Inc., LA Weekly profiles; weekly podcast). Best route: pitch Bachman a podcast-guest/partnership angle via IG DM + LinkedIn; use Sunbiz address for direct mail. | P2: ~700 employees, 400+ creators (Supercreator listing); $2B+ creator sales claim on site | Q2: https://www.creatorsinc.com/ · https://www.supercreator.app/agencies | R2: 1 | S2: 5 | T2: 3 | U2: 3 | V2: 4 | W2: 5 | X2: =ROUND((S2*'Scoring Model'!$B$5+T2*'Scoring Model'!$B$6+U2*'Scoring Model'!$B$7+V2*'Scoring Model'!$B$8+W2*'Scoring Model'!$B$9)/5*100,0) | Y2: =INDEX('Scoring Model'!$B$14:$B$17,MATCH(X2,'Scoring Model'!$A$14:$A$17,1)) | Z2: =MOD(TIME(9,5,0)-F2/24,1) | AA2: =IF(TIME(9,5,0)-F2/24<0,"previous day (ET)","same day") | AC2: Largest roster found. Also the most natural strategic acquirer for TTS. Runs CI Swimwear show at Miami Swim Week = in-person window (late May/early June). | AD2: Acquirer track — see Acquirers tab
A3: 2 | B3: AROA Agency | C3: Miami, FL (HQ) · UK/ES/RO/UA/PT-BR sites | D3: USA / UK | E3: America/New_York (EDT) | F3: 0 | G3: not published | H3: — | I3: office@aroaagency.com (verified on site footer, Sept 2026) | J3: aroaagency.com/uk/contact (form) | K3: not published | L3: Telegram t.me/aroaagency1 · YouTube @aroa_agency | M3: not published | N3: 8101 Biscayne Blvd, Ph 703-24, Miami, FL 33138 (site footer) | O3: Email + Telegram published. Ask office@ for the founder/partnerships lead by name. Attends XBIZ/AVN (logos on site) = meet in person. | P3: 30+ 'elite' creators, 150+ global team, 10+ yrs in adult industry; has a 'Refer Creators' program | Q3: https://aroaagency.com/uk | R3: 1 | S3: 3 | T3: 5 | U3: 4 | V3: 4 | W3: 5 | X3: =ROUND((S3*'Scoring Model'!$B$5+T3*'Scoring Model'!$B$6+U3*'Scoring Model'!$B$7+V3*'Scoring Model'!$B$8+W3*'Scoring Model'!$B$9)/5*100,0) | Y3: =INDEX('Scoring Model'!$B$14:$B$17,MATCH(X3,'Scoring Model'!$A$14:$A$17,1)) | Z3: =MOD(TIME(9,5,0)-F3/24,1) | AA3: =IF(TIME(9,5,0)-F3/24<0,"previous day (ET)","same day") | AC3: Most reachable Tier-1. Referral culture = receptive to a weekly talent program. Multilingual (RO/UA/ES/PT) — could seed non-US creators. | AD3: Acquirer track — see Acquirers tab
A4: 3 | B4: Louna's Models | C4: Los Angeles (founded 2018) · Paris · Miami · Milan | D4: USA / France | E4: America/Los_Angeles (PDT) | F4: -3 | G4: Louna | H4: Founder (former top creator) | I4: not published | J4: Supercreator listing → agency site (verify) | K4: verify | L4: Runs the 'Exclu Awards LA' creator event | M4: not published | N4: not published | O4: Founder is the public face; approach via IG DM to Louna + event sponsorship/partnership ask. | P4: 'Exclusive network of international talents'; female-only agency | Q4: https://www.supercreator.app/agencies | R4: 1 | S4: 3 | T4: 4 | U4: 4 | V4: 4 | W4: 5 | X4: =ROUND((S4*'Scoring Model'!$B$5+T4*'Scoring Model'!$B$6+U4*'Scoring Model'!$B$7+V4*'Scoring Model'!$B$8+W4*'Scoring Model'!$B$9)/5*100,0) | Y4: =INDEX('Scoring Model'!$B$14:$B$17,MATCH(X4,'Scoring Model'!$A$14:$A$17,1)) | Z4: =MOD(TIME(9,5,0)-F4/24,1) | AA4: =IF(TIME(9,5,0)-F4/24<0,"previous day (ET)","same day") | AC4: Event owner = pitch a TTS award category / live vote at Exclu Awards. Four cities = multi-timezone roster. | AD4: Acquirer track — see Acquirers tab
A5: 4 | B5: SheX Agency | C5: Germany (DACH) | D5: Germany | E5: Europe/Berlin (CEST) | F5: 6 | G5: Named in Impressum (verify at she-x.de/impressum) | H5: Geschäftsführer (per Impressum) | I5: in Impressum (verify) | J5: she-x.de | K5: @onlyfans_agentur (13K) | L5: Trustpilot 4.8 (132 reviews) | M5: in Impressum (verify) | N5: in Impressum (verify) | O5: German law requires a named responsible person + email + address on the Impressum page — the cleanest direct contact in the whole list. | P5: Claims 450+ staff and 'largest' management for OnlyFans, 4based, BestFans, Fancentro, Maloum (Trustpilot company blurb) | Q5: https://ca.trustpilot.com/review/she-x.de · https://www.instagram.com/onlyfans_agentur/ | R5: 1 | S5: 5 | T5: 4 | U5: 4 | V5: 4 | W5: 2 | X5: =ROUND((S5*'Scoring Model'!$B$5+T5*'Scoring Model'!$B$6+U5*'Scoring Model'!$B$7+V5*'Scoring Model'!$B$8+W5*'Scoring Model'!$B$9)/5*100,0) | Y5: =INDEX('Scoring Model'!$B$14:$B$17,MATCH(X5,'Scoring Model'!$A$14:$A$17,1)) | Z5: =MOD(TIME(9,5,0)-F5/24,1) | AA5: =IF(TIME(9,5,0)-F5/24<0,"previous day (ET)","same day") | AC5: Multi-platform (not OF-only) → less TOS-sensitive to off-platform promo. Big DACH roster. Write in English; offer German landing copy. | AD5: Acquirer track — see Acquirers tab
A6: 5 | B6: Rare X Network / Rare Agency | C6: USA (verify city) | D6: USA | E6: America/New_York (verify) | F6: 0 | G6: not published | H6: — | I6: not published | J6: rareagency.net | K6: verify | L6: — | M6: not published | N6: not published | O6: Matching network that places creators with many agencies — one partnership = multi-agency reach. Approach as co-marketing partner, not as a single agency. | P6: Network of partner agencies; free matching for creators (CreditDonkey review) | Q6: https://www.rareagency.net/ · https://www.creditdonkey.com/best-onlyfans-agency.html | R6: 1 | S6: 3 | T6: 3 | U6: 4 | V6: 4 | W6: 2 | X6: =ROUND((S6*'Scoring Model'!$B$5+T6*'Scoring Model'!$B$6+U6*'Scoring Model'!$B$7+V6*'Scoring Model'!$B$8+W6*'Scoring Model'!$B$9)/5*100,0) | Y6: =INDEX('Scoring Model'!$B$14:$B$17,MATCH(X6,'Scoring Model'!$A$14:$A$17,1)) | Z6: =MOD(TIME(9,5,0)-F6/24,1) | AA6: =IF(TIME(9,5,0)-F6/24<0,"previous day (ET)","same day") | AC6: Channel multiplier. Offer: TTS as a perk they hand every placed creator. | AD6: Weekly enlistment — demand evidence
